{
 "cells": [
  {
   "cell_type": "code",
   "execution_count": 9,
   "id": "bcf8998b",
   "metadata": {},
   "outputs": [
    {
     "name": "stdout",
     "output_type": "stream",
     "text": [
      "ERROR! Session/line number was not unique in database. History logging moved to new session 335\n"
     ]
    }
   ],
   "source": [
    "import numpy as np\n",
    "import pandas as pd\n",
    "import tensorflow as tf\n",
    "import tensorflow.keras\n",
    "from tensorflow.keras.models import Sequential\n",
    "from tensorflow.keras.layers import Dense, Activation\n",
    "from tensorflow.keras.callbacks import EarlyStopping\n",
    "import matplotlib.pyplot as plt "
   ]
  },
  {
   "cell_type": "code",
   "execution_count": 10,
   "id": "52833354",
   "metadata": {},
   "outputs": [],
   "source": [
    "#importing MNIST Dataset Exploration\n",
    "(X_train, y_train), (x_test, y_test) = ts.keras.datasets.mnist.load_data() #load the data"
   ]
  },
  {
   "cell_type": "code",
   "execution_count": 11,
   "id": "91db3cbb",
   "metadata": {},
   "outputs": [
    {
     "name": "stdout",
     "output_type": "stream",
     "text": [
      "(60000, 28, 28)\n",
      "(28, 28)\n"
     ]
    }
   ],
   "source": [
    "print(X_train.shape) #mnist data set has 60000 sample with 28 28 matrix dimensions\n",
    "print(X_train[0].shape) #each element"
   ]
  },
  {
   "cell_type": "code",
   "execution_count": 12,
   "id": "f29a3536",
   "metadata": {},
   "outputs": [
    {
     "name": "stdout",
     "output_type": "stream",
     "text": [
      "(60000,)\n"
     ]
    }
   ],
   "source": [
    "print(y_train.shape) #mnsist data set label dimenasionality"
   ]
  },
  {
   "cell_type": "code",
   "execution_count": 13,
   "id": "f34548db",
   "metadata": {},
   "outputs": [],
   "source": [
    "#prepare the train mnist data for autoencoder\n",
    "#normalize the train mnist data for range between 0 and 1 and flatten 28x28 data\n",
    "X_train = X_train.astype('float32')/255\n",
    "X_train = X_train.reshape((len(X_train), np.prod(X_train.shape[1:])))"
   ]
  },
  {
   "cell_type": "code",
   "execution_count": null,
   "id": "d69a8b79",
   "metadata": {},
   "outputs": [
    {
     "name": "stderr",
     "output_type": "stream",
     "text": [
      "ERROR:root:Internal Python error in the inspect module.\n",
      "Below is the traceback from this internal error.\n",
      "\n",
      "ERROR:root:Internal Python error in the inspect module.\n",
      "Below is the traceback from this internal error.\n",
      "\n",
      "ERROR:root:Internal Python error in the inspect module.\n",
      "Below is the traceback from this internal error.\n",
      "\n"
     ]
    },
    {
     "name": "stdout",
     "output_type": "stream",
     "text": [
      "float32\n",
      "Traceback (most recent call last):\n",
      "  File \"C:\\Users\\user\\miniconda3\\envs\\tensorflow\\lib\\site-packages\\IPython\\core\\interactiveshell.py\", line 3441, in run_code\n",
      "    exec(code_obj, self.user_global_ns, self.user_ns)\n",
      "  File \"C:\\Users\\user\\AppData\\Local\\Temp/ipykernel_12780/61923812.py\", line 15, in <module>\n",
      "    model.fit(X_train, X_train, verbose=0, epochs=20)\n",
      "  File \"C:\\Users\\user\\miniconda3\\envs\\tensorflow\\lib\\site-packages\\tensorflow_core\\python\\keras\\engine\\training.py\", line 819, in fit\n",
      "    use_multiprocessing=use_multiprocessing)\n",
      "  File \"C:\\Users\\user\\miniconda3\\envs\\tensorflow\\lib\\site-packages\\tensorflow_core\\python\\keras\\engine\\training_v2.py\", line 235, in fit\n",
      "    use_multiprocessing=use_multiprocessing)\n",
      "  File \"C:\\Users\\user\\miniconda3\\envs\\tensorflow\\lib\\site-packages\\tensorflow_core\\python\\keras\\engine\\training_v2.py\", line 593, in _process_training_inputs\n",
      "    use_multiprocessing=use_multiprocessing)\n",
      "  File \"C:\\Users\\user\\miniconda3\\envs\\tensorflow\\lib\\site-packages\\tensorflow_core\\python\\keras\\engine\\training_v2.py\", line 646, in _process_inputs\n",
      "    x, y, sample_weight=sample_weights)\n",
      "  File \"C:\\Users\\user\\miniconda3\\envs\\tensorflow\\lib\\site-packages\\tensorflow_core\\python\\keras\\engine\\training.py\", line 2383, in _standardize_user_data\n",
      "    batch_size=batch_size)\n",
      "  File \"C:\\Users\\user\\miniconda3\\envs\\tensorflow\\lib\\site-packages\\tensorflow_core\\python\\keras\\engine\\training.py\", line 2410, in _standardize_tensors\n",
      "    exception_prefix='input')\n",
      "  File \"C:\\Users\\user\\miniconda3\\envs\\tensorflow\\lib\\site-packages\\tensorflow_core\\python\\keras\\engine\\training_utils.py\", line 573, in standardize_input_data\n",
      "    'with shape ' + str(data_shape))\n",
      "ValueError: Error when checking input: expected input_1 to have 3 dimensions, but got array with shape (60000, 784)\n",
      "\n",
      "During handling of the above exception, another exception occurred:\n",
      "\n",
      "Traceback (most recent call last):\n",
      "  File \"C:\\Users\\user\\miniconda3\\envs\\tensorflow\\lib\\site-packages\\IPython\\core\\interactiveshell.py\", line 2061, in showtraceback\n",
      "    stb = value._render_traceback_()\n",
      "AttributeError: 'ValueError' object has no attribute '_render_traceback_'\n",
      "\n",
      "During handling of the above exception, another exception occurred:\n",
      "\n",
      "Traceback (most recent call last):\n",
      "  File \"C:\\Users\\user\\miniconda3\\envs\\tensorflow\\lib\\site-packages\\IPython\\core\\ultratb.py\", line 1101, in get_records\n",
      "    return _fixed_getinnerframes(etb, number_of_lines_of_context, tb_offset)\n",
      "  File \"C:\\Users\\user\\miniconda3\\envs\\tensorflow\\lib\\site-packages\\IPython\\core\\ultratb.py\", line 248, in wrapped\n",
      "    return f(*args, **kwargs)\n",
      "  File \"C:\\Users\\user\\miniconda3\\envs\\tensorflow\\lib\\site-packages\\IPython\\core\\ultratb.py\", line 281, in _fixed_getinnerframes\n",
      "    records = fix_frame_records_filenames(inspect.getinnerframes(etb, context))\n",
      "  File \"C:\\Users\\user\\miniconda3\\envs\\tensorflow\\lib\\inspect.py\", line 1502, in getinnerframes\n",
      "    frameinfo = (tb.tb_frame,) + getframeinfo(tb, context)\n",
      "  File \"C:\\Users\\user\\miniconda3\\envs\\tensorflow\\lib\\inspect.py\", line 1460, in getframeinfo\n",
      "    filename = getsourcefile(frame) or getfile(frame)\n",
      "  File \"C:\\Users\\user\\miniconda3\\envs\\tensorflow\\lib\\inspect.py\", line 696, in getsourcefile\n",
      "    if getattr(getmodule(object, filename), '__loader__', None) is not None:\n",
      "  File \"C:\\Users\\user\\miniconda3\\envs\\tensorflow\\lib\\inspect.py\", line 733, in getmodule\n",
      "    if ismodule(module) and hasattr(module, '__file__'):\n",
      "  File \"C:\\Users\\user\\miniconda3\\envs\\tensorflow\\lib\\site-packages\\tensorflow\\__init__.py\", line 50, in __getattr__\n",
      "    module = self._load()\n",
      "  File \"C:\\Users\\user\\miniconda3\\envs\\tensorflow\\lib\\site-packages\\tensorflow\\__init__.py\", line 44, in _load\n",
      "    module = _importlib.import_module(self.__name__)\n",
      "  File \"C:\\Users\\user\\miniconda3\\envs\\tensorflow\\lib\\importlib\\__init__.py\", line 127, in import_module\n",
      "    return _bootstrap._gcd_import(name[level:], package, level)\n",
      "  File \"<frozen importlib._bootstrap>\", line 1006, in _gcd_import\n",
      "  File \"<frozen importlib._bootstrap>\", line 983, in _find_and_load\n",
      "  File \"<frozen importlib._bootstrap>\", line 965, in _find_and_load_unlocked\n",
      "ModuleNotFoundError: No module named 'tensorflow_core.estimator'\n",
      "Traceback (most recent call last):\n",
      "  File \"C:\\Users\\user\\miniconda3\\envs\\tensorflow\\lib\\site-packages\\IPython\\core\\interactiveshell.py\", line 3441, in run_code\n",
      "    exec(code_obj, self.user_global_ns, self.user_ns)\n",
      "  File \"C:\\Users\\user\\AppData\\Local\\Temp/ipykernel_12780/61923812.py\", line 15, in <module>\n",
      "    model.fit(X_train, X_train, verbose=0, epochs=20)\n",
      "  File \"C:\\Users\\user\\miniconda3\\envs\\tensorflow\\lib\\site-packages\\tensorflow_core\\python\\keras\\engine\\training.py\", line 819, in fit\n",
      "    use_multiprocessing=use_multiprocessing)\n",
      "  File \"C:\\Users\\user\\miniconda3\\envs\\tensorflow\\lib\\site-packages\\tensorflow_core\\python\\keras\\engine\\training_v2.py\", line 235, in fit\n",
      "    use_multiprocessing=use_multiprocessing)\n",
      "  File \"C:\\Users\\user\\miniconda3\\envs\\tensorflow\\lib\\site-packages\\tensorflow_core\\python\\keras\\engine\\training_v2.py\", line 593, in _process_training_inputs\n",
      "    use_multiprocessing=use_multiprocessing)\n",
      "  File \"C:\\Users\\user\\miniconda3\\envs\\tensorflow\\lib\\site-packages\\tensorflow_core\\python\\keras\\engine\\training_v2.py\", line 646, in _process_inputs\n",
      "    x, y, sample_weight=sample_weights)\n",
      "  File \"C:\\Users\\user\\miniconda3\\envs\\tensorflow\\lib\\site-packages\\tensorflow_core\\python\\keras\\engine\\training.py\", line 2383, in _standardize_user_data\n",
      "    batch_size=batch_size)\n",
      "  File \"C:\\Users\\user\\miniconda3\\envs\\tensorflow\\lib\\site-packages\\tensorflow_core\\python\\keras\\engine\\training.py\", line 2410, in _standardize_tensors\n",
      "    exception_prefix='input')\n",
      "  File \"C:\\Users\\user\\miniconda3\\envs\\tensorflow\\lib\\site-packages\\tensorflow_core\\python\\keras\\engine\\training_utils.py\", line 573, in standardize_input_data\n",
      "    'with shape ' + str(data_shape))\n",
      "ValueError: Error when checking input: expected input_1 to have 3 dimensions, but got array with shape (60000, 784)\n",
      "\n",
      "During handling of the above exception, another exception occurred:\n",
      "\n",
      "Traceback (most recent call last):\n",
      "  File \"C:\\Users\\user\\miniconda3\\envs\\tensorflow\\lib\\site-packages\\IPython\\core\\interactiveshell.py\", line 2061, in showtraceback\n",
      "    stb = value._render_traceback_()\n",
      "AttributeError: 'ValueError' object has no attribute '_render_traceback_'\n",
      "\n",
      "During handling of the above exception, another exception occurred:\n",
      "\n",
      "Traceback (most recent call last):\n",
      "  File \"C:\\Users\\user\\miniconda3\\envs\\tensorflow\\lib\\site-packages\\IPython\\core\\interactiveshell.py\", line 3361, in run_ast_nodes\n",
      "    if (await self.run_code(code, result,  async_=asy)):\n",
      "  File \"C:\\Users\\user\\miniconda3\\envs\\tensorflow\\lib\\site-packages\\IPython\\core\\interactiveshell.py\", line 3458, in run_code\n",
      "    self.showtraceback(running_compiled_code=True)\n",
      "  File \"C:\\Users\\user\\miniconda3\\envs\\tensorflow\\lib\\site-packages\\IPython\\core\\interactiveshell.py\", line 2064, in showtraceback\n",
      "    value, tb, tb_offset=tb_offset)\n",
      "  File \"C:\\Users\\user\\miniconda3\\envs\\tensorflow\\lib\\site-packages\\IPython\\core\\ultratb.py\", line 1368, in structured_traceback\n",
      "    self, etype, value, tb, tb_offset, number_of_lines_of_context)\n",
      "  File \"C:\\Users\\user\\miniconda3\\envs\\tensorflow\\lib\\site-packages\\IPython\\core\\ultratb.py\", line 1268, in structured_traceback\n",
      "    self, etype, value, tb, tb_offset, number_of_lines_of_context\n",
      "  File \"C:\\Users\\user\\miniconda3\\envs\\tensorflow\\lib\\site-packages\\IPython\\core\\ultratb.py\", line 1125, in structured_traceback\n",
      "    tb_offset)\n",
      "  File \"C:\\Users\\user\\miniconda3\\envs\\tensorflow\\lib\\site-packages\\IPython\\core\\ultratb.py\", line 1082, in format_exception_as_a_whole\n",
      "    last_unique, recursion_repeat = find_recursion(orig_etype, evalue, records)\n",
      "  File \"C:\\Users\\user\\miniconda3\\envs\\tensorflow\\lib\\site-packages\\IPython\\core\\ultratb.py\", line 382, in find_recursion\n",
      "    return len(records), 0\n",
      "TypeError: object of type 'NoneType' has no len()\n",
      "\n",
      "During handling of the above exception, another exception occurred:\n",
      "\n",
      "Traceback (most recent call last):\n",
      "  File \"C:\\Users\\user\\miniconda3\\envs\\tensorflow\\lib\\site-packages\\IPython\\core\\interactiveshell.py\", line 2061, in showtraceback\n",
      "    stb = value._render_traceback_()\n",
      "AttributeError: 'TypeError' object has no attribute '_render_traceback_'\n",
      "\n",
      "During handling of the above exception, another exception occurred:\n",
      "\n",
      "Traceback (most recent call last):\n",
      "  File \"C:\\Users\\user\\miniconda3\\envs\\tensorflow\\lib\\site-packages\\IPython\\core\\ultratb.py\", line 1101, in get_records\n",
      "    return _fixed_getinnerframes(etb, number_of_lines_of_context, tb_offset)\n",
      "  File \"C:\\Users\\user\\miniconda3\\envs\\tensorflow\\lib\\site-packages\\IPython\\core\\ultratb.py\", line 248, in wrapped\n",
      "    return f(*args, **kwargs)\n",
      "  File \"C:\\Users\\user\\miniconda3\\envs\\tensorflow\\lib\\site-packages\\IPython\\core\\ultratb.py\", line 281, in _fixed_getinnerframes\n",
      "    records = fix_frame_records_filenames(inspect.getinnerframes(etb, context))\n",
      "  File \"C:\\Users\\user\\miniconda3\\envs\\tensorflow\\lib\\inspect.py\", line 1502, in getinnerframes\n",
      "    frameinfo = (tb.tb_frame,) + getframeinfo(tb, context)\n",
      "  File \"C:\\Users\\user\\miniconda3\\envs\\tensorflow\\lib\\inspect.py\", line 1460, in getframeinfo\n",
      "    filename = getsourcefile(frame) or getfile(frame)\n",
      "  File \"C:\\Users\\user\\miniconda3\\envs\\tensorflow\\lib\\inspect.py\", line 696, in getsourcefile\n",
      "    if getattr(getmodule(object, filename), '__loader__', None) is not None:\n",
      "  File \"C:\\Users\\user\\miniconda3\\envs\\tensorflow\\lib\\inspect.py\", line 733, in getmodule\n",
      "    if ismodule(module) and hasattr(module, '__file__'):\n",
      "  File \"C:\\Users\\user\\miniconda3\\envs\\tensorflow\\lib\\site-packages\\tensorflow\\__init__.py\", line 50, in __getattr__\n",
      "    module = self._load()\n",
      "  File \"C:\\Users\\user\\miniconda3\\envs\\tensorflow\\lib\\site-packages\\tensorflow\\__init__.py\", line 44, in _load\n",
      "    module = _importlib.import_module(self.__name__)\n",
      "  File \"C:\\Users\\user\\miniconda3\\envs\\tensorflow\\lib\\importlib\\__init__.py\", line 127, in import_module\n",
      "    return _bootstrap._gcd_import(name[level:], package, level)\n",
      "  File \"<frozen importlib._bootstrap>\", line 1006, in _gcd_import\n",
      "  File \"<frozen importlib._bootstrap>\", line 983, in _find_and_load\n",
      "  File \"<frozen importlib._bootstrap>\", line 965, in _find_and_load_unlocked\n",
      "ModuleNotFoundError: No module named 'tensorflow_core.estimator'\n"
     ]
    },
    {
     "name": "stdout",
     "output_type": "stream",
     "text": [
      "Traceback (most recent call last):\n",
      "  File \"C:\\Users\\user\\miniconda3\\envs\\tensorflow\\lib\\site-packages\\IPython\\core\\interactiveshell.py\", line 3441, in run_code\n",
      "    exec(code_obj, self.user_global_ns, self.user_ns)\n",
      "  File \"C:\\Users\\user\\AppData\\Local\\Temp/ipykernel_12780/61923812.py\", line 15, in <module>\n",
      "    model.fit(X_train, X_train, verbose=0, epochs=20)\n",
      "  File \"C:\\Users\\user\\miniconda3\\envs\\tensorflow\\lib\\site-packages\\tensorflow_core\\python\\keras\\engine\\training.py\", line 819, in fit\n",
      "    use_multiprocessing=use_multiprocessing)\n",
      "  File \"C:\\Users\\user\\miniconda3\\envs\\tensorflow\\lib\\site-packages\\tensorflow_core\\python\\keras\\engine\\training_v2.py\", line 235, in fit\n",
      "    use_multiprocessing=use_multiprocessing)\n",
      "  File \"C:\\Users\\user\\miniconda3\\envs\\tensorflow\\lib\\site-packages\\tensorflow_core\\python\\keras\\engine\\training_v2.py\", line 593, in _process_training_inputs\n",
      "    use_multiprocessing=use_multiprocessing)\n",
      "  File \"C:\\Users\\user\\miniconda3\\envs\\tensorflow\\lib\\site-packages\\tensorflow_core\\python\\keras\\engine\\training_v2.py\", line 646, in _process_inputs\n",
      "    x, y, sample_weight=sample_weights)\n",
      "  File \"C:\\Users\\user\\miniconda3\\envs\\tensorflow\\lib\\site-packages\\tensorflow_core\\python\\keras\\engine\\training.py\", line 2383, in _standardize_user_data\n",
      "    batch_size=batch_size)\n",
      "  File \"C:\\Users\\user\\miniconda3\\envs\\tensorflow\\lib\\site-packages\\tensorflow_core\\python\\keras\\engine\\training.py\", line 2410, in _standardize_tensors\n",
      "    exception_prefix='input')\n",
      "  File \"C:\\Users\\user\\miniconda3\\envs\\tensorflow\\lib\\site-packages\\tensorflow_core\\python\\keras\\engine\\training_utils.py\", line 573, in standardize_input_data\n",
      "    'with shape ' + str(data_shape))\n",
      "ValueError: Error when checking input: expected input_1 to have 3 dimensions, but got array with shape (60000, 784)\n",
      "\n",
      "During handling of the above exception, another exception occurred:\n",
      "\n",
      "Traceback (most recent call last):\n",
      "  File \"C:\\Users\\user\\miniconda3\\envs\\tensorflow\\lib\\site-packages\\IPython\\core\\interactiveshell.py\", line 2061, in showtraceback\n",
      "    stb = value._render_traceback_()\n",
      "AttributeError: 'ValueError' object has no attribute '_render_traceback_'\n",
      "\n",
      "During handling of the above exception, another exception occurred:\n",
      "\n",
      "Traceback (most recent call last):\n",
      "  File \"C:\\Users\\user\\miniconda3\\envs\\tensorflow\\lib\\site-packages\\IPython\\core\\interactiveshell.py\", line 3361, in run_ast_nodes\n",
      "    if (await self.run_code(code, result,  async_=asy)):\n",
      "  File \"C:\\Users\\user\\miniconda3\\envs\\tensorflow\\lib\\site-packages\\IPython\\core\\interactiveshell.py\", line 3458, in run_code\n",
      "    self.showtraceback(running_compiled_code=True)\n",
      "  File \"C:\\Users\\user\\miniconda3\\envs\\tensorflow\\lib\\site-packages\\IPython\\core\\interactiveshell.py\", line 2064, in showtraceback\n",
      "    value, tb, tb_offset=tb_offset)\n",
      "  File \"C:\\Users\\user\\miniconda3\\envs\\tensorflow\\lib\\site-packages\\IPython\\core\\ultratb.py\", line 1368, in structured_traceback\n",
      "    self, etype, value, tb, tb_offset, number_of_lines_of_context)\n",
      "  File \"C:\\Users\\user\\miniconda3\\envs\\tensorflow\\lib\\site-packages\\IPython\\core\\ultratb.py\", line 1268, in structured_traceback\n",
      "    self, etype, value, tb, tb_offset, number_of_lines_of_context\n",
      "  File \"C:\\Users\\user\\miniconda3\\envs\\tensorflow\\lib\\site-packages\\IPython\\core\\ultratb.py\", line 1125, in structured_traceback\n",
      "    tb_offset)\n",
      "  File \"C:\\Users\\user\\miniconda3\\envs\\tensorflow\\lib\\site-packages\\IPython\\core\\ultratb.py\", line 1082, in format_exception_as_a_whole\n",
      "    last_unique, recursion_repeat = find_recursion(orig_etype, evalue, records)\n",
      "  File \"C:\\Users\\user\\miniconda3\\envs\\tensorflow\\lib\\site-packages\\IPython\\core\\ultratb.py\", line 382, in find_recursion\n",
      "    return len(records), 0\n",
      "TypeError: object of type 'NoneType' has no len()\n",
      "\n",
      "During handling of the above exception, another exception occurred:\n",
      "\n",
      "Traceback (most recent call last):\n",
      "  File \"C:\\Users\\user\\miniconda3\\envs\\tensorflow\\lib\\site-packages\\IPython\\core\\interactiveshell.py\", line 2061, in showtraceback\n",
      "    stb = value._render_traceback_()\n",
      "AttributeError: 'TypeError' object has no attribute '_render_traceback_'\n",
      "\n",
      "During handling of the above exception, another exception occurred:\n",
      "\n",
      "Traceback (most recent call last):\n",
      "  File \"C:\\Users\\user\\miniconda3\\envs\\tensorflow\\lib\\site-packages\\IPython\\core\\interactiveshell.py\", line 2944, in _run_cell\n",
      "    return runner(coro)\n",
      "  File \"C:\\Users\\user\\miniconda3\\envs\\tensorflow\\lib\\site-packages\\IPython\\core\\async_helpers.py\", line 68, in _pseudo_sync_runner\n",
      "    coro.send(None)\n",
      "  File \"C:\\Users\\user\\miniconda3\\envs\\tensorflow\\lib\\site-packages\\IPython\\core\\interactiveshell.py\", line 3170, in run_cell_async\n",
      "    interactivity=interactivity, compiler=compiler, result=result)\n",
      "  File \"C:\\Users\\user\\miniconda3\\envs\\tensorflow\\lib\\site-packages\\IPython\\core\\interactiveshell.py\", line 3380, in run_ast_nodes\n",
      "    self.showtraceback()\n",
      "  File \"C:\\Users\\user\\miniconda3\\envs\\tensorflow\\lib\\site-packages\\IPython\\core\\interactiveshell.py\", line 2064, in showtraceback\n",
      "    value, tb, tb_offset=tb_offset)\n",
      "  File \"C:\\Users\\user\\miniconda3\\envs\\tensorflow\\lib\\site-packages\\IPython\\core\\ultratb.py\", line 1368, in structured_traceback\n",
      "    self, etype, value, tb, tb_offset, number_of_lines_of_context)\n",
      "  File \"C:\\Users\\user\\miniconda3\\envs\\tensorflow\\lib\\site-packages\\IPython\\core\\ultratb.py\", line 1268, in structured_traceback\n",
      "    self, etype, value, tb, tb_offset, number_of_lines_of_context\n",
      "  File \"C:\\Users\\user\\miniconda3\\envs\\tensorflow\\lib\\site-packages\\IPython\\core\\ultratb.py\", line 1143, in structured_traceback\n",
      "    chained_exceptions_tb_offset)\n",
      "  File \"C:\\Users\\user\\miniconda3\\envs\\tensorflow\\lib\\site-packages\\IPython\\core\\ultratb.py\", line 1082, in format_exception_as_a_whole\n",
      "    last_unique, recursion_repeat = find_recursion(orig_etype, evalue, records)\n",
      "  File \"C:\\Users\\user\\miniconda3\\envs\\tensorflow\\lib\\site-packages\\IPython\\core\\ultratb.py\", line 382, in find_recursion\n",
      "    return len(records), 0\n",
      "TypeError: object of type 'NoneType' has no len()\n",
      "\n",
      "During handling of the above exception, another exception occurred:\n",
      "\n",
      "Traceback (most recent call last):\n",
      "  File \"C:\\Users\\user\\miniconda3\\envs\\tensorflow\\lib\\site-packages\\IPython\\core\\interactiveshell.py\", line 2061, in showtraceback\n",
      "    stb = value._render_traceback_()\n",
      "AttributeError: 'TypeError' object has no attribute '_render_traceback_'\n",
      "\n",
      "During handling of the above exception, another exception occurred:\n",
      "\n",
      "Traceback (most recent call last):\n",
      "  File \"C:\\Users\\user\\miniconda3\\envs\\tensorflow\\lib\\site-packages\\IPython\\core\\ultratb.py\", line 1101, in get_records\n",
      "    return _fixed_getinnerframes(etb, number_of_lines_of_context, tb_offset)\n",
      "  File \"C:\\Users\\user\\miniconda3\\envs\\tensorflow\\lib\\site-packages\\IPython\\core\\ultratb.py\", line 248, in wrapped\n",
      "    return f(*args, **kwargs)\n",
      "  File \"C:\\Users\\user\\miniconda3\\envs\\tensorflow\\lib\\site-packages\\IPython\\core\\ultratb.py\", line 281, in _fixed_getinnerframes\n",
      "    records = fix_frame_records_filenames(inspect.getinnerframes(etb, context))\n",
      "  File \"C:\\Users\\user\\miniconda3\\envs\\tensorflow\\lib\\inspect.py\", line 1502, in getinnerframes\n",
      "    frameinfo = (tb.tb_frame,) + getframeinfo(tb, context)\n",
      "  File \"C:\\Users\\user\\miniconda3\\envs\\tensorflow\\lib\\inspect.py\", line 1460, in getframeinfo\n",
      "    filename = getsourcefile(frame) or getfile(frame)\n",
      "  File \"C:\\Users\\user\\miniconda3\\envs\\tensorflow\\lib\\inspect.py\", line 696, in getsourcefile\n",
      "    if getattr(getmodule(object, filename), '__loader__', None) is not None:\n",
      "  File \"C:\\Users\\user\\miniconda3\\envs\\tensorflow\\lib\\inspect.py\", line 733, in getmodule\n",
      "    if ismodule(module) and hasattr(module, '__file__'):\n",
      "  File \"C:\\Users\\user\\miniconda3\\envs\\tensorflow\\lib\\site-packages\\tensorflow\\__init__.py\", line 50, in __getattr__\n",
      "    module = self._load()\n",
      "  File \"C:\\Users\\user\\miniconda3\\envs\\tensorflow\\lib\\site-packages\\tensorflow\\__init__.py\", line 44, in _load\n",
      "    module = _importlib.import_module(self.__name__)\n",
      "  File \"C:\\Users\\user\\miniconda3\\envs\\tensorflow\\lib\\importlib\\__init__.py\", line 127, in import_module\n",
      "    return _bootstrap._gcd_import(name[level:], package, level)\n",
      "  File \"<frozen importlib._bootstrap>\", line 1006, in _gcd_import\n",
      "  File \"<frozen importlib._bootstrap>\", line 983, in _find_and_load\n",
      "  File \"<frozen importlib._bootstrap>\", line 965, in _find_and_load_unlocked\n",
      "ModuleNotFoundError: No module named 'tensorflow_core.estimator'\n"
     ]
    }
   ],
   "source": [
    "#autoencoder is a neural network type that learns from unlabelled data and take same input and same ouput type \n",
    "#we will train our autoencoder with MNIST data set digit image representations and take the prediction output representations\n",
    "#First we built our autoencoder neural network layers (Sequential) \n",
    "# a compression autoencoder that has a simple framework\n",
    "from tensorflow.keras.optimizers import Adam\n",
    "print(X_train.dtype)\n",
    "\n",
    "model = Sequential()\n",
    "model.add(tf.keras.Input(shape=(28, 28))) #input layer\n",
    "model.add(Dense(128, activation='sigmoid')) #first hidden layer of encoder\n",
    "model.add(Dense(32, activation='sigmoid')) #coding layer \n",
    "model.add(Dense(128, activation='sigmoid')) #first hidden layer of decoder \n",
    "model.add(Dense(784, activation='sigmoid')) #last layer \n",
    "model.compile(loss='mean_squared_error', optimizer=Adam(lr=0.01))\n",
    "model.fit(X_train, X_train, verbose=0, epochs=20)"
   ]
  },
  {
   "cell_type": "code",
   "execution_count": null,
   "id": "27af2731",
   "metadata": {},
   "outputs": [],
   "source": []
  },
  {
   "cell_type": "code",
   "execution_count": null,
   "id": "20662600",
   "metadata": {},
   "outputs": [],
   "source": []
  },
  {
   "cell_type": "code",
   "execution_count": null,
   "id": "be204216",
   "metadata": {},
   "outputs": [],
   "source": []
  }
 ],
 "metadata": {
  "kernelspec": {
   "display_name": "Python 3.6 (tensorflow)",
   "language": "python",
   "name": "tensorflow"
  },
  "language_info": {
   "codemirror_mode": {
    "name": "ipython",
    "version": 3
   },
   "file_extension": ".py",
   "mimetype": "text/x-python",
   "name": "python",
   "nbconvert_exporter": "python",
   "pygments_lexer": "ipython3",
   "version": "3.7.11"
  }
 },
 "nbformat": 4,
 "nbformat_minor": 5
}
